<?xml version="1.0" ?>
<!-- =================================================================================== -->
<!-- |    This document was autogenerated by xacro from robot_body.xacro               | -->
<!-- |    EDITING THIS FILE BY HAND IS NOT RECOMMENDED                                 | -->
<!-- =================================================================================== -->
<robot name="robot">
  <!-- Specify some standard inertial calculations https://en.wikipedia.org/wiki/List_of_moments_of_inertia -->
  <!-- These make use of xacro's mathematical functionality -->
  <material name="white">
    <color rgba="1 1 1 1"/>
  </material>
  <material name="orange">
    <color rgba="1 0.3 0.3 1"/>
  </material>
  <material name="blue">
    <color rgba="0.2 0.2 1 1"/>
  </material>
  <material name="black">
    <color rgba="0 0 0 1"/>
  </material>
  <!--common practice to create a base link . commonly placed on centre-->
  <link name="base_link">  

    </link>
  <joint name="chassis_joint" type="revolute">
    <parent link="base_link"/>
    <child link="chassis"/>
    <origin xyz="0.1 0 0"/>
    <axis xyz="0 1 0"/>
    <limit effort="10000" lower="-1.57" upper="1.57" velocity="100.0"/>
  </joint>
  <link name="chassis">
    <visual>
      <origin xyz="0 0 0"/>
      <material name="white"/>
      <geometry>
        <box size="0.15 0.10 0.05"/>
      </geometry>
    </visual>
  </link>
  <joint name="servo1_joint_1" type="revolute">
    <parent link="chassis"/>
    <child link="servo1_link_1"/>
    <origin xyz="0.026 0 0"/>
    <axis xyz="1 0 0"/>
    <limit effort="10000" lower="-1.57" upper="1.57" velocity="100.0"/>
  </joint>
  <link name="servo1_link_1">
    <visual>
      <origin xyz="0 0 -0.0675"/>
      <material name="blue"/>
      <geometry>
        <box size="0.002 0.018 0.135"/>
      </geometry>
    </visual>
    <collision>
      <origin xyz="0 0 -0.0675"/>
      <material name="blue"/>
      <geometry>
        <box size="0.002 0.018 0.135"/>
      </geometry>
    </collision>
    <inertial>
      <origin rpy="0 0 0" xyz="0.15 0 0.075"/>
      <mass value="0.5"/>
      <inertia ixx="0.004687499999999999" ixy="0.0" ixz="0.0" iyy="0.004687499999999999" iyz="0.0" izz="0.0075"/>
    </inertial>
  </link>
  <joint name="servo2_joint_1" type="revolute">
    <parent link="servo1_link_1"/>
    <child link="servo2_link_1"/>
    <origin xyz="0.002 0 -0.130"/>
    <axis xyz="1 0 0"/>
    <limit effort="10000" lower="-1.57" upper="1.57" velocity="100.0"/>
  </joint>
  <link name="servo2_link_1">
    <visual>
      <origin xyz="0 0 -0.0675"/>
      <material name="blue"/>
      <geometry>
        <box size="0.002 0.018 0.135"/>
      </geometry>
    </visual>
    <collision>
      <origin xyz="0 0 -0.0675"/>
      <material name="blue"/>
      <geometry>
        <box size="0.002 0.018 0.135"/>
      </geometry>
    </collision>
    <inertial>
      <origin rpy="0 0 0" xyz="0.15 0 0.075"/>
      <mass value="0.5"/>
      <inertia ixx="0.004687499999999999" ixy="0.0" ixz="0.0" iyy="0.004687499999999999" iyz="0.0" izz="0.0075"/>
    </inertial>
  </link>
</robot>
